<?xml version='1.0'?>
<robot xmlns:xacro="http://www.ros.org/wiki/xacro">

  <!-- Robot properties -->
  <xacro:property name="wheelbase" value="0.440" />
  <xacro:property name="wheel_radius" value="0.070" />
  <xacro:property name="wheel_thickness" value="0.025" />
  <!-- z_sep = 35mm + 6mm -->
  <xacro:property name="wheel_zsep" value="0.041" />

  <!-- Macro for robot wheels -->
  <xacro:macro name="drive_wheel" params="name reflect">
    <link name="${name}_link">
      <visual>
        <origin xyz="0 0 0" rpy="${pi / 2} 0 0" />
        <geometry>
          <mesh filename="package://romaa_description/meshes/romaa_drive_wheel.stl" />
        </geometry>
        <material name="light_gray" />
      </visual>
      <inertial>
        <origin xyz="0 0 0" rpy="${pi / 2} 0 0" />
        <mass value="0.200" />
        <inertia ixx="0.0003179237060191715" ixy="0" ixz="0"
            iyy="0.00031792370601916626" iyz="0" izz="0.0006167682575358206" />
      </inertial>
      <collision>
        <origin xyz="0 0 0" rpy="${pi / 2} 0 0" />
        <geometry>
          <cylinder length="${wheel_thickness}" radius="${wheel_radius}" />
        </geometry>
      </collision>
    </link>
    <joint name="${name}_joint" type="continuous">
      <!-- <dynamics damping="0.1" friction="0.1" />  -->
      <origin xyz="0 ${reflect * wheelbase / 2} ${wheel_zsep}" rpy="0 0 0" />
      <parent link="base_link" />
      <child link="${name}_link" />
      <axis xyz="0 1 0" />
    </joint>
  </xacro:macro>

</robot>
